Workbook

Sheet Cómo completar
B1: CÓMO COMPLETAR LA PLANTILLA DE PRESUPUESTO
B2: Se completa en la hoja «Presupuesto». Al terminar se importa desde el sistema: Presupuestos → 📥 Importar desde Excel.
B4: 1 | C4: Arriba: Obra, Descripción, Fecha, Elaboró y el Sector general (si todo el presupuesto es de un mismo sector).
B5: 2 | C5: COPIAR Y PEGAR DESDE OTRA PLANILLA: copiá juntas las columnas Descripción · Unidad · Cantidad · M. obra · Material (en ese orden) y pegá con un clic en la celda D9.
B6: 3 | C6: Podés pegar también las filas de título de capítulo (ej. «MAMPOSTERÍA»): se reconocen solas, no suman, y las filas de abajo toman ese capítulo.
B7: 4 | C7: Si una cantidad o un precio sale mal después de pegar, pegá de nuevo con Ctrl + Shift + V → «Valores».
B8: 5 | C8: También se puede cargar a mano: una fila por trabajo. La Cantidad acepta la medición como fórmula. Ej.: =4,5*3+1,96*3
B9: 6 | C9: El Costo unitario, el Parcial, el N° y el Total se calculan solos (columnas grises).
B10: 7 | C10: Mirá arriba a la derecha: tiene que decir «✓ Todo OK». Si dice «N fila(s) a revisar», buscá en la columna Control las filas en rojo.
B11: 8 | C11: No cambies los títulos ni el orden de las columnas: el sistema los usa para importar.
B13: Leyenda
C14: Amarillo: lo completa o pega el residente
C15: Gris: se calcula solo, no se toca
C16: «Título de capítulo»: fila de título, no suma
B18: Ejemplo
C19: La hoja «Presupuesto» trae cargado el Presupuesto 68 (Nivel 3 · Edificio Orquídeas). Para uno nuevo, borrá las celdas amarillas (seleccioná B9:K1008 → Suprimir) y pegá o cargá el tuyo.
C22: Resumen elaborado por Conexdata

Sheet Presupuesto
D1: PRESUPUESTO DE OBRA
D2: Completá o pegá en las celdas amarillas · una fila por trabajo · lo gris se calcula solo
B4: Obra | C4: EDIFICIO ORQUÍDEAS | H4: Fecha | I4: 22/06/2026 | K4: TOTAL DEL PRESUPUESTO | L4: Trabajos
B5: Descripción | C5: Presupuesto 68 · Nivel 3 | H5: Elaboró | I5: Ing. Azucena | K5: =SUM(J9:J1008) -> 2.3765684e+08 | L5: =COUNTIF(N9:N1008,"W") -> 29
B6: Sector general | C6: Nivel 3 | E6: ← se usa en las filas sin sector | L6: =IF(COUNTIF(L9:L1008,"✓ OK")=L5,"✓ Todo OK",(L5-COUNTIF(L9:L1008,"✓ OK"))&" fila(s) a revisar") -> ✓ Todo OK
A8: N° | B8: Sector | C8: Capítulo | D8: Descripción del trabajo | E8: Unidad | F8: Cantidad | G8: M. obra ₲ / unidad | H8: Material ₲ / unidad | I8: Costo unit. ₲ / unidad | J8: Parcial ₲ | K8: Observación (opcional) | L8: Control | M8: cap | N8: tipo | O8: 0
A9: =IF(N9="W",COUNTIF(N$9:N9,"W"),"") -> 1 | B9: Nivel 3 | C9: PRELIMINARES | D9: Marcación y replanteo Piso 3 | E9: m2 | F9: 618 | G9: 500 | H9: 3000 | I9: =IF(N9="W",IFERROR(N(G9)+N(H9),0),"") -> 3500 | J9: =IF(N9="W",IFERROR(N(F9)*I9,0),"") -> 2163000 | L9: =IF(N9="","",IF(N9="T","Título de capítulo",IF(OR(ISERROR(F9),ISERROR(G9),ISERROR(H9)),"Error en fórmula: pegá como valores",IF(AND(B9="",$C$6=""),"Falta sector",IF(M9="","Falta capítulo",IF(TRIM(E9)="","Falta unidad",IF(NOT((COUNTIF(Listas!$A$2:$A$40,E9)+COUNTIF(Listas!$D$2:$D$60,E9)>0)),"Unidad no reconocida",IF(AND(F9<>"",NOT(ISNUMBER(F9))),"Cantidad no es número",IF(N(F9)<=0,"Falta cantidad",IF(OR(AND(G9<>"",NOT(ISNUMBER(G9))),AND(H9<>"",NOT(ISNUMBER(H9)))),"Precio no es número",IF(N(G9)+N(H9)<=0,"Falta precio","✓ OK"))))))))))) -> ✓ OK | M9: =IF(N9<>"W","",IF(TRIM(C9)<>"",TRIM(C9),IFERROR(LOOKUP(2,1/(N$9:N9="T"),D$9:D9),""))) -> PRELIMINARES | N9: =IF(TRIM(D9)="","",IF(AND(TRIM(E9)="",IFERROR(N(F9),1)=0,IFERROR(N(G9)+N(H9),1)=0),"T","W")) -> W | O9: =IF(M9="","",IF(COUNTIF(M$9:M9,M9)=1,MAX(O$8:O8)+1,"")) -> 1
A10: =IF(N10="W",COUNTIF(N$9:N10,"W"),"") -> 2 | B10: Nivel 3 | C10: PRELIMINARES | D10: Demolición de mampostería de 0.15m de ladrillo hueco | E10: m2 | F10: =21.5*2.95 -> 63.425 | G10: 20000 | H10: 0 | I10: =IF(N10="W",IFERROR(N(G10)+N(H10),0),"") -> 20000 | J10: =IF(N10="W",IFERROR(N(F10)*I10,0),"") -> 1268500 | L10: =IF(N10="","",IF(N10="T","Título de capítulo",IF(OR(ISERROR(F10),ISERROR(G10),ISERROR(H10)),"Error en fórmula: pegá como valores",IF(AND(B10="",$C$6=""),"Falta sector",IF(M10="","Falta capítulo",IF(TRIM(E10)="","Falta unidad",IF(NOT((COUNTIF(Listas!$A$2:$A$40,E10)+COUNTIF(Listas!$D$2:$D$60,E10)>0)),"Unidad no reconocida",IF(AND(F10<>"",NOT(ISNUMBER(F10))),"Cantidad no es número",IF(N(F10)<=0,"Falta cantidad",IF(OR(AND(G10<>"",NOT(ISNUMBER(G10))),AND(H10<>"",NOT(ISNUMBER(H10)))),"Precio no es número",IF(N(G10)+N(H10)<=0,"Falta precio","✓ OK"))))))))))) -> ✓ OK | M10: =IF(N10<>"W","",IF(TRIM(C10)<>"",TRIM(C10),IFERROR(LOOKUP(2,1/(N$9:N10="T"),D$9:D10),""))) -> PRELIMINARES | N10: =IF(TRIM(D10)="","",IF(AND(TRIM(E10)="",IFERROR(N(F10),1)=0,IFERROR(N(G10)+N(H10),1)=0),"T","W")) -> W | O10: =IF(M10="","",IF(COUNTIF(M$9:M10,M10)=1,MAX(O$8:O9)+1,""))
A11: =IF(N11="W",COUNTIF(N$9:N11,"W"),"") -> 3 | B11: Nivel 3 | C11: MAMPOSTERÍA | D11: Mampostería de 0,20m hueco | E11: m2 | F11: =4.5*3+1.96*3+21.96*3+26.35*3+5*3+1.5*3 -> 183.81 | G11: 45000 | H11: =50*1300+7*1340+0.03*15000+0.06*160000 -> 84430 | I11: =IF(N11="W",IFERROR(N(G11)+N(H11),0),"") -> 129430 | J11: =IF(N11="W",IFERROR(N(F11)*I11,0),"") -> 23790528 | L11: =IF(N11="","",IF(N11="T","Título de capítulo",IF(OR(ISERROR(F11),ISERROR(G11),ISERROR(H11)),"Error en fórmula: pegá como valores",IF(AND(B11="",$C$6=""),"Falta sector",IF(M11="","Falta capítulo",IF(TRIM(E11)="","Falta unidad",IF(NOT((COUNTIF(Listas!$A$2:$A$40,E11)+COUNTIF(Listas!$D$2:$D$60,E11)>0)),"Unidad no reconocida",IF(AND(F11<>"",NOT(ISNUMBER(F11))),"Cantidad no es número",IF(N(F11)<=0,"Falta cantidad",IF(OR(AND(G11<>"",NOT(ISNUMBER(G11))),AND(H11<>"",NOT(ISNUMBER(H11)))),"Precio no es número",IF(N(G11)+N(H11)<=0,"Falta precio","✓ OK"))))))))))) -> ✓ OK | M11: =IF(N11<>"W","",IF(TRIM(C11)<>"",TRIM(C11),IFERROR(LOOKUP(2,1/(N$9:N11="T"),D$9:D11),""))) -> MAMPOSTERÍA | N11: =IF(TRIM(D11)="","",IF(AND(TRIM(E11)="",IFERROR(N(F11),1)=0,IFERROR(N(G11)+N(H11),1)=0),"T","W")) -> W | O11: =IF(M11="","",IF(COUNTIF(M$9:M11,M11)=1,MAX(O$8:O10)+1,"")) -> 2
A12: =IF(N12="W",COUNTIF(N$9:N12,"W"),"") -> 4 | B12: Nivel 3 | C12: MAMPOSTERÍA | D12: Mampostería de encuñamiento | E12: ml | F12: =4.5+1.96+21.96+26.35 -> 54.77 | G12: 35000 | H12: 20388 | I12: =IF(N12="W",IFERROR(N(G12)+N(H12),0),"") -> 55388 | J12: =IF(N12="W",IFERROR(N(F12)*I12,0),"") -> 3033600.8 | L12: =IF(N12="","",IF(N12="T","Título de capítulo",IF(OR(ISERROR(F12),ISERROR(G12),ISERROR(H12)),"Error en fórmula: pegá como valores",IF(AND(B12="",$C$6=""),"Falta sector",IF(M12="","Falta capítulo",IF(TRIM(E12)="","Falta unidad",IF(NOT((COUNTIF(Listas!$A$2:$A$40,E12)+COUNTIF(Listas!$D$2:$D$60,E12)>0)),"Unidad no reconocida",IF(AND(F12<>"",NOT(ISNUMBER(F12))),"Cantidad no es número",IF(N(F12)<=0,"Falta cantidad",IF(OR(AND(G12<>"",NOT(ISNUMBER(G12))),AND(H12<>"",NOT(ISNUMBER(H12)))),"Precio no es número",IF(N(G12)+N(H12)<=0,"Falta precio","✓ OK"))))))))))) -> ✓ OK | M12: =IF(N12<>"W","",IF(TRIM(C12)<>"",TRIM(C12),IFERROR(LOOKUP(2,1/(N$9:N12="T"),D$9:D12),""))) -> MAMPOSTERÍA | N12: =IF(TRIM(D12)="","",IF(AND(TRIM(E12)="",IFERROR(N(F12),1)=0,IFERROR(N(G12)+N(H12),1)=0),"T","W")) -> W | O12: =IF(M12="","",IF(COUNTIF(M$9:M12,M12)=1,MAX(O$8:O11)+1,""))
A13: =IF(N13="W",COUNTIF(N$9:N13,"W"),"") -> 5 | B13: Nivel 3 | C13: MAMPOSTERÍA | D13: Envarillado de amarre de muros con pilares y esquinas | E13: m | F13: =4.5*3+1.96*3+21.96+26.35 -> 67.69 | G13: 15000 | H13: 12975 | I13: =IF(N13="W",IFERROR(N(G13)+N(H13),0),"") -> 27975 | J13: =IF(N13="W",IFERROR(N(F13)*I13,0),"") -> 1893627.8 | L13: =IF(N13="","",IF(N13="T","Título de capítulo",IF(OR(ISERROR(F13),ISERROR(G13),ISERROR(H13)),"Error en fórmula: pegá como valores",IF(AND(B13="",$C$6=""),"Falta sector",IF(M13="","Falta capítulo",IF(TRIM(E13)="","Falta unidad",IF(NOT((COUNTIF(Listas!$A$2:$A$40,E13)+COUNTIF(Listas!$D$2:$D$60,E13)>0)),"Unidad no reconocida",IF(AND(F13<>"",NOT(ISNUMBER(F13))),"Cantidad no es número",IF(N(F13)<=0,"Falta cantidad",IF(OR(AND(G13<>"",NOT(ISNUMBER(G13))),AND(H13<>"",NOT(ISNUMBER(H13)))),"Precio no es número",IF(N(G13)+N(H13)<=0,"Falta precio","✓ OK"))))))))))) -> ✓ OK | M13: =IF(N13<>"W","",IF(TRIM(C13)<>"",TRIM(C13),IFERROR(LOOKUP(2,1/(N$9:N13="T"),D$9:D13),""))) -> MAMPOSTERÍA | N13: =IF(TRIM(D13)="","",IF(AND(TRIM(E13)="",IFERROR(N(F13),1)=0,IFERROR(N(G13)+N(H13),1)=0),"T","W")) -> W | O13: =IF(M13="","",IF(COUNTIF(M$9:M13,M13)=1,MAX(O$8:O12)+1,""))
A14: =IF(N14="W",COUNTIF(N$9:N14,"W"),"") -> 6 | B14: Nivel 3 | C14: MAMPOSTERÍA | D14: Anclaje de varillas al H° existente, paquete de 4 varillas | E14: un | F14: =3+2+2+2+2+2+2 -> 15 | G14: 30000 | H14: =125000*(4/12) -> 41666.667 | I14: =IF(N14="W",IFERROR(N(G14)+N(H14),0),"") -> 71666.667 | J14: =IF(N14="W",IFERROR(N(F14)*I14,0),"") -> 1075000 | L14: =IF(N14="","",IF(N14="T","Título de capítulo",IF(OR(ISERROR(F14),ISERROR(G14),ISERROR(H14)),"Error en fórmula: pegá como valores",IF(AND(B14="",$C$6=""),"Falta sector",IF(M14="","Falta capítulo",IF(TRIM(E14)="","Falta unidad",IF(NOT((COUNTIF(Listas!$A$2:$A$40,E14)+COUNTIF(Listas!$D$2:$D$60,E14)>0)),"Unidad no reconocida",IF(AND(F14<>"",NOT(ISNUMBER(F14))),"Cantidad no es número",IF(N(F14)<=0,"Falta cantidad",IF(OR(AND(G14<>"",NOT(ISNUMBER(G14))),AND(H14<>"",NOT(ISNUMBER(H14)))),"Precio no es número",IF(N(G14)+N(H14)<=0,"Falta precio","✓ OK"))))))))))) -> ✓ OK | M14: =IF(N14<>"W","",IF(TRIM(C14)<>"",TRIM(C14),IFERROR(LOOKUP(2,1/(N$9:N14="T"),D$9:D14),""))) -> MAMPOSTERÍA | N14: =IF(TRIM(D14)="","",IF(AND(TRIM(E14)="",IFERROR(N(F14),1)=0,IFERROR(N(G14)+N(H14),1)=0),"T","W")) -> W | O14: =IF(M14="","",IF(COUNTIF(M$9:M14,M14)=1,MAX(O$8:O13)+1,""))
A15: =IF(N15="W",COUNTIF(N$9:N15,"W"),"") -> 7 | B15: Nivel 3 | C15: MAMPOSTERÍA | D15: Relleno de losa rebajada con ladrillo hueco | E15: m2 | F15: =5.15*3.4 -> 17.51 | G15: =40000+5000 -> 45000 | H15: 1321.76 | I15: =IF(N15="W",IFERROR(N(G15)+N(H15),0),"") -> 46321.76 | J15: =IF(N15="W",IFERROR(N(F15)*I15,0),"") -> 811094.02 | L15: =IF(N15="","",IF(N15="T","Título de capítulo",IF(OR(ISERROR(F15),ISERROR(G15),ISERROR(H15)),"Error en fórmula: pegá como valores",IF(AND(B15="",$C$6=""),"Falta sector",IF(M15="","Falta capítulo",IF(TRIM(E15)="","Falta unidad",IF(NOT((COUNTIF(Listas!$A$2:$A$40,E15)+COUNTIF(Listas!$D$2:$D$60,E15)>0)),"Unidad no reconocida",IF(AND(F15<>"",NOT(ISNUMBER(F15))),"Cantidad no es número",IF(N(F15)<=0,"Falta cantidad",IF(OR(AND(G15<>"",NOT(ISNUMBER(G15))),AND(H15<>"",NOT(ISNUMBER(H15)))),"Precio no es número",IF(N(G15)+N(H15)<=0,"Falta precio","✓ OK"))))))))))) -> ✓ OK | M15: =IF(N15<>"W","",IF(TRIM(C15)<>"",TRIM(C15),IFERROR(LOOKUP(2,1/(N$9:N15="T"),D$9:D15),""))) -> MAMPOSTERÍA | N15: =IF(TRIM(D15)="","",IF(AND(TRIM(E15)="",IFERROR(N(F15),1)=0,IFERROR(N(G15)+N(H15),1)=0),"T","W")) -> W | O15: =IF(M15="","",IF(COUNTIF(M$9:M15,M15)=1,MAX(O$8:O14)+1,""))
A16: =IF(N16="W",COUNTIF(N$9:N16,"W"),"") -> 8 | B16: Nivel 3 | C16: REVOQUES | D16: Salpicado de ladrillos huecos con hidrofugo | E16: m2 | F16: =6.49*3+6.14*3+21.96*3+5*3*2+1.5*3*2+16.1*3 -> 191.07 | G16: 5000 | H16: =0.5*1100+0.03*140000 -> 4750 | I16: =IF(N16="W",IFERROR(N(G16)+N(H16),0),"") -> 9750 | J16: =IF(N16="W",IFERROR(N(F16)*I16,0),"") -> 1862932.5 | L16: =IF(N16="","",IF(N16="T","Título de capítulo",IF(OR(ISERROR(F16),ISERROR(G16),ISERROR(H16)),"Error en fórmula: pegá como valores",IF(AND(B16="",$C$6=""),"Falta sector",IF(M16="","Falta capítulo",IF(TRIM(E16)="","Falta unidad",IF(NOT((COUNTIF(Listas!$A$2:$A$40,E16)+COUNTIF(Listas!$D$2:$D$60,E16)>0)),"Unidad no reconocida",IF(AND(F16<>"",NOT(ISNUMBER(F16))),"Cantidad no es número",IF(N(F16)<=0,"Falta cantidad",IF(OR(AND(G16<>"",NOT(ISNUMBER(G16))),AND(H16<>"",NOT(ISNUMBER(H16)))),"Precio no es número",IF(N(G16)+N(H16)<=0,"Falta precio","✓ OK"))))))))))) -> ✓ OK | M16: =IF(N16<>"W","",IF(TRIM(C16)<>"",TRIM(C16),IFERROR(LOOKUP(2,1/(N$9:N16="T"),D$9:D16),""))) -> REVOQUES | N16: =IF(TRIM(D16)="","",IF(AND(TRIM(E16)="",IFERROR(N(F16),1)=0,IFERROR(N(G16)+N(H16),1)=0),"T","W")) -> W | O16: =IF(M16="","",IF(COUNTIF(M$9:M16,M16)=1,MAX(O$8:O15)+1,"")) -> 3
A17: =IF(N17="W",COUNTIF(N$9:N17,"W"),"") -> 9 | B17: Nivel 3 | C17: REVOQUES | D17: Revoques de muros de ladrillos huecos con hidrofugo | E17: m2 | F17: 191.07 | G17: 50000 | H17: 28450 | I17: =IF(N17="W",IFERROR(N(G17)+N(H17),0),"") -> 78450 | J17: =IF(N17="W",IFERROR(N(F17)*I17,0),"") -> 14989442 | L17: =IF(N17="","",IF(N17="T","Título de capítulo",IF(OR(ISERROR(F17),ISERROR(G17),ISERROR(H17)),"Error en fórmula: pegá como valores",IF(AND(B17="",$C$6=""),"Falta sector",IF(M17="","Falta capítulo",IF(TRIM(E17)="","Falta unidad",IF(NOT((COUNTIF(Listas!$A$2:$A$40,E17)+COUNTIF(Listas!$D$2:$D$60,E17)>0)),"Unidad no reconocida",IF(AND(F17<>"",NOT(ISNUMBER(F17))),"Cantidad no es número",IF(N(F17)<=0,"Falta cantidad",IF(OR(AND(G17<>"",NOT(ISNUMBER(G17))),AND(H17<>"",NOT(ISNUMBER(H17)))),"Precio no es número",IF(N(G17)+N(H17)<=0,"Falta precio","✓ OK"))))))))))) -> ✓ OK | M17: =IF(N17<>"W","",IF(TRIM(C17)<>"",TRIM(C17),IFERROR(LOOKUP(2,1/(N$9:N17="T"),D$9:D17),""))) -> REVOQUES | N17: =IF(TRIM(D17)="","",IF(AND(TRIM(E17)="",IFERROR(N(F17),1)=0,IFERROR(N(G17)+N(H17),1)=0),"T","W")) -> W | O17: =IF(M17="","",IF(COUNTIF(M$9:M17,M17)=1,MAX(O$8:O16)+1,""))
A18: =IF(N18="W",COUNTIF(N$9:N18,"W"),"") -> 10 | B18: Nivel 3 | C18: REVOQUES | D18: Demolición de mamposteria de durlock | E18: m2 | F18: =6.3*3 -> 18.9 | G18: 15000 | H18: 0 | I18: =IF(N18="W",IFERROR(N(G18)+N(H18),0),"") -> 15000 | J18: =IF(N18="W",IFERROR(N(F18)*I18,0),"") -> 283500 | L18: =IF(N18="","",IF(N18="T","Título de capítulo",IF(OR(ISERROR(F18),ISERROR(G18),ISERROR(H18)),"Error en fórmula: pegá como valores",IF(AND(B18="",$C$6=""),"Falta sector",IF(M18="","Falta capítulo",IF(TRIM(E18)="","Falta unidad",IF(NOT((COUNTIF(Listas!$A$2:$A$40,E18)+COUNTIF(Listas!$D$2:$D$60,E18)>0)),"Unidad no reconocida",IF(AND(F18<>"",NOT(ISNUMBER(F18))),"Cantidad no es número",IF(N(F18)<=0,"Falta cantidad",IF(OR(AND(G18<>"",NOT(ISNUMBER(G18))),AND(H18<>"",NOT(ISNUMBER(H18)))),"Precio no es número",IF(N(G18)+N(H18)<=0,"Falta precio","✓ OK"))))))))))) -> ✓ OK | M18: =IF(N18<>"W","",IF(TRIM(C18)<>"",TRIM(C18),IFERROR(LOOKUP(2,1/(N$9:N18="T"),D$9:D18),""))) -> REVOQUES | N18: =IF(TRIM(D18)="","",IF(AND(TRIM(E18)="",IFERROR(N(F18),1)=0,IFERROR(N(G18)+N(H18),1)=0),"T","W")) -> W | O18: =IF(M18="","",IF(COUNTIF(M$9:M18,M18)=1,MAX(O$8:O17)+1,""))
A19: =IF(N19="W",COUNTIF(N$9:N19,"W"),"") -> 11 | B19: Nivel 3 | C19: REVOQUES | D19: Demolición de revoque viejo de mamposteria | E19: m2 | F19: =3.68*2.95+3.83*2.95+5.58*2.95+6.14*2.95 -> 56.7285 | G19: 10000 | H19: 0 | I19: =IF(N19="W",IFERROR(N(G19)+N(H19),0),"") -> 10000 | J19: =IF(N19="W",IFERROR(N(F19)*I19,0),"") -> 567285 | L19: =IF(N19="","",IF(N19="T","Título de capítulo",IF(OR(ISERROR(F19),ISERROR(G19),ISERROR(H19)),"Error en fórmula: pegá como valores",IF(AND(B19="",$C$6=""),"Falta sector",IF(M19="","Falta capítulo",IF(TRIM(E19)="","Falta unidad",IF(NOT((COUNTIF(Listas!$A$2:$A$40,E19)+COUNTIF(Listas!$D$2:$D$60,E19)>0)),"Unidad no reconocida",IF(AND(F19<>"",NOT(ISNUMBER(F19))),"Cantidad no es número",IF(N(F19)<=0,"Falta cantidad",IF(OR(AND(G19<>"",NOT(ISNUMBER(G19))),AND(H19<>"",NOT(ISNUMBER(H19)))),"Precio no es número",IF(N(G19)+N(H19)<=0,"Falta precio","✓ OK"))))))))))) -> ✓ OK | M19: =IF(N19<>"W","",IF(TRIM(C19)<>"",TRIM(C19),IFERROR(LOOKUP(2,1/(N$9:N19="T"),D$9:D19),""))) -> REVOQUES | N19: =IF(TRIM(D19)="","",IF(AND(TRIM(E19)="",IFERROR(N(F19),1)=0,IFERROR(N(G19)+N(H19),1)=0),"T","W")) -> W | O19: =IF(M19="","",IF(COUNTIF(M$9:M19,M19)=1,MAX(O$8:O18)+1,""))
A20: =IF(N20="W",COUNTIF(N$9:N20,"W"),"") -> 12 | B20: Nivel 3 | C20: REVOQUES | D20: Salpicado de cielorraso de losa con hidrófugo | E20: m2 | F20: 459.38 | G20: 10000 | H20: 12584 | I20: =IF(N20="W",IFERROR(N(G20)+N(H20),0),"") -> 22584 | J20: =IF(N20="W",IFERROR(N(F20)*I20,0),"") -> 10374638 | L20: =IF(N20="","",IF(N20="T","Título de capítulo",IF(OR(ISERROR(F20),ISERROR(G20),ISERROR(H20)),"Error en fórmula: pegá como valores",IF(AND(B20="",$C$6=""),"Falta sector",IF(M20="","Falta capítulo",IF(TRIM(E20)="","Falta unidad",IF(NOT((COUNTIF(Listas!$A$2:$A$40,E20)+COUNTIF(Listas!$D$2:$D$60,E20)>0)),"Unidad no reconocida",IF(AND(F20<>"",NOT(ISNUMBER(F20))),"Cantidad no es número",IF(N(F20)<=0,"Falta cantidad",IF(OR(AND(G20<>"",NOT(ISNUMBER(G20))),AND(H20<>"",NOT(ISNUMBER(H20)))),"Precio no es número",IF(N(G20)+N(H20)<=0,"Falta precio","✓ OK"))))))))))) -> ✓ OK | M20: =IF(N20<>"W","",IF(TRIM(C20)<>"",TRIM(C20),IFERROR(LOOKUP(2,1/(N$9:N20="T"),D$9:D20),""))) -> REVOQUES | N20: =IF(TRIM(D20)="","",IF(AND(TRIM(E20)="",IFERROR(N(F20),1)=0,IFERROR(N(G20)+N(H20),1)=0),"T","W")) -> W | O20: =IF(M20="","",IF(COUNTIF(M$9:M20,M20)=1,MAX(O$8:O19)+1,""))
A21: =IF(N21="W",COUNTIF(N$9:N21,"W"),"") -> 13 | B21: Nivel 3 | C21: REVOQUES | D21: Revoque de cielorraso de losa con hidrófugo a dos capas | E21: m2 | F21: 459.38 | G21: 55000 | H21: 46458 | I21: =IF(N21="W",IFERROR(N(G21)+N(H21),0),"") -> 101458 | J21: =IF(N21="W",IFERROR(N(F21)*I21,0),"") -> 46607776 | L21: =IF(N21="","",IF(N21="T","Título de capítulo",IF(OR(ISERROR(F21),ISERROR(G21),ISERROR(H21)),"Error en fórmula: pegá como valores",IF(AND(B21="",$C$6=""),"Falta sector",IF(M21="","Falta capítulo",IF(TRIM(E21)="","Falta unidad",IF(NOT((COUNTIF(Listas!$A$2:$A$40,E21)+COUNTIF(Listas!$D$2:$D$60,E21)>0)),"Unidad no reconocida",IF(AND(F21<>"",NOT(ISNUMBER(F21))),"Cantidad no es número",IF(N(F21)<=0,"Falta cantidad",IF(OR(AND(G21<>"",NOT(ISNUMBER(G21))),AND(H21<>"",NOT(ISNUMBER(H21)))),"Precio no es número",IF(N(G21)+N(H21)<=0,"Falta precio","✓ OK"))))))))))) -> ✓ OK | M21: =IF(N21<>"W","",IF(TRIM(C21)<>"",TRIM(C21),IFERROR(LOOKUP(2,1/(N$9:N21="T"),D$9:D21),""))) -> REVOQUES | N21: =IF(TRIM(D21)="","",IF(AND(TRIM(E21)="",IFERROR(N(F21),1)=0,IFERROR(N(G21)+N(H21),1)=0),"T","W")) -> W | O21: =IF(M21="","",IF(COUNTIF(M$9:M21,M21)=1,MAX(O$8:O20)+1,""))
A22: =IF(N22="W",COUNTIF(N$9:N22,"W"),"") -> 14 | B22: Nivel 3 | C22: REVOQUES | D22: Demolición de revoque viejo de losa | E22: m2 | F22: 459.38 | G22: 15000 | H22: 0 | I22: =IF(N22="W",IFERROR(N(G22)+N(H22),0),"") -> 15000 | J22: =IF(N22="W",IFERROR(N(F22)*I22,0),"") -> 6890700 | L22: =IF(N22="","",IF(N22="T","Título de capítulo",IF(OR(ISERROR(F22),ISERROR(G22),ISERROR(H22)),"Error en fórmula: pegá como valores",IF(AND(B22="",$C$6=""),"Falta sector",IF(M22="","Falta capítulo",IF(TRIM(E22)="","Falta unidad",IF(NOT((COUNTIF(Listas!$A$2:$A$40,E22)+COUNTIF(Listas!$D$2:$D$60,E22)>0)),"Unidad no reconocida",IF(AND(F22<>"",NOT(ISNUMBER(F22))),"Cantidad no es número",IF(N(F22)<=0,"Falta cantidad",IF(OR(AND(G22<>"",NOT(ISNUMBER(G22))),AND(H22<>"",NOT(ISNUMBER(H22)))),"Precio no es número",IF(N(G22)+N(H22)<=0,"Falta precio","✓ OK"))))))))))) -> ✓ OK | M22: =IF(N22<>"W","",IF(TRIM(C22)<>"",TRIM(C22),IFERROR(LOOKUP(2,1/(N$9:N22="T"),D$9:D22),""))) -> REVOQUES | N22: =IF(TRIM(D22)="","",IF(AND(TRIM(E22)="",IFERROR(N(F22),1)=0,IFERROR(N(G22)+N(H22),1)=0),"T","W")) -> W | O22: =IF(M22="","",IF(COUNTIF(M$9:M22,M22)=1,MAX(O$8:O21)+1,""))
A23: =IF(N23="W",COUNTIF(N$9:N23,"W"),"") -> 15 | B23: Nivel 3 | C23: REVOQUES | D23: Revoque de mochetas en vigas | E23: ml | F23: =(29.65*12+19.31*7)*3 -> 1472.91 | G23: 25000 | H23: 13234 | I23: =IF(N23="W",IFERROR(N(G23)+N(H23),0),"") -> 38234 | J23: =IF(N23="W",IFERROR(N(F23)*I23,0),"") -> 56315241 | L23: =IF(N23="","",IF(N23="T","Título de capítulo",IF(OR(ISERROR(F23),ISERROR(G23),ISERROR(H23)),"Error en fórmula: pegá como valores",IF(AND(B23="",$C$6=""),"Falta sector",IF(M23="","Falta capítulo",IF(TRIM(E23)="","Falta unidad",IF(NOT((COUNTIF(Listas!$A$2:$A$40,E23)+COUNTIF(Listas!$D$2:$D$60,E23)>0)),"Unidad no reconocida",IF(AND(F23<>"",NOT(ISNUMBER(F23))),"Cantidad no es número",IF(N(F23)<=0,"Falta cantidad",IF(OR(AND(G23<>"",NOT(ISNUMBER(G23))),AND(H23<>"",NOT(ISNUMBER(H23)))),"Precio no es número",IF(N(G23)+N(H23)<=0,"Falta precio","✓ OK"))))))))))) -> ✓ OK | M23: =IF(N23<>"W","",IF(TRIM(C23)<>"",TRIM(C23),IFERROR(LOOKUP(2,1/(N$9:N23="T"),D$9:D23),""))) -> REVOQUES | N23: =IF(TRIM(D23)="","",IF(AND(TRIM(E23)="",IFERROR(N(F23),1)=0,IFERROR(N(G23)+N(H23),1)=0),"T","W")) -> W | O23: =IF(M23="","",IF(COUNTIF(M$9:M23,M23)=1,MAX(O$8:O22)+1,""))
A24: =IF(N24="W",COUNTIF(N$9:N24,"W"),"") -> 16 | B24: Nivel 3 | C24: REVOQUES | D24: Demolición de revoque viejo en vigas 3 caras | E24: ml | F24: 490.97 | G24: =(0.36+0.36+0.18)*15000 -> 13500 | H24: 0 | I24: =IF(N24="W",IFERROR(N(G24)+N(H24),0),"") -> 13500 | J24: =IF(N24="W",IFERROR(N(F24)*I24,0),"") -> 6628095 | L24: =IF(N24="","",IF(N24="T","Título de capítulo",IF(OR(ISERROR(F24),ISERROR(G24),ISERROR(H24)),"Error en fórmula: pegá como valores",IF(AND(B24="",$C$6=""),"Falta sector",IF(M24="","Falta capítulo",IF(TRIM(E24)="","Falta unidad",IF(NOT((COUNTIF(Listas!$A$2:$A$40,E24)+COUNTIF(Listas!$D$2:$D$60,E24)>0)),"Unidad no reconocida",IF(AND(F24<>"",NOT(ISNUMBER(F24))),"Cantidad no es número",IF(N(F24)<=0,"Falta cantidad",IF(OR(AND(G24<>"",NOT(ISNUMBER(G24))),AND(H24<>"",NOT(ISNUMBER(H24)))),"Precio no es número",IF(N(G24)+N(H24)<=0,"Falta precio","✓ OK"))))))))))) -> ✓ OK | M24: =IF(N24<>"W","",IF(TRIM(C24)<>"",TRIM(C24),IFERROR(LOOKUP(2,1/(N$9:N24="T"),D$9:D24),""))) -> REVOQUES | N24: =IF(TRIM(D24)="","",IF(AND(TRIM(E24)="",IFERROR(N(F24),1)=0,IFERROR(N(G24)+N(H24),1)=0),"T","W")) -> W | O24: =IF(M24="","",IF(COUNTIF(M$9:M24,M24)=1,MAX(O$8:O23)+1,""))
A25: =IF(N25="W",COUNTIF(N$9:N25,"W"),"") -> 17 | B25: Nivel 3 | C25: REVOQUES | D25: Revoque de mocheta en Pilares (menor a 40 cm) | E25: ml | F25: =2.95*(2+2+2+2+2+2+4+4+4+3) -> 79.65 | G25: 25000 | H25: 13234 | I25: =IF(N25="W",IFERROR(N(G25)+N(H25),0),"") -> 38234 | J25: =IF(N25="W",IFERROR(N(F25)*I25,0),"") -> 3045338.1 | L25: =IF(N25="","",IF(N25="T","Título de capítulo",IF(OR(ISERROR(F25),ISERROR(G25),ISERROR(H25)),"Error en fórmula: pegá como valores",IF(AND(B25="",$C$6=""),"Falta sector",IF(M25="","Falta capítulo",IF(TRIM(E25)="","Falta unidad",IF(NOT((COUNTIF(Listas!$A$2:$A$40,E25)+COUNTIF(Listas!$D$2:$D$60,E25)>0)),"Unidad no reconocida",IF(AND(F25<>"",NOT(ISNUMBER(F25))),"Cantidad no es número",IF(N(F25)<=0,"Falta cantidad",IF(OR(AND(G25<>"",NOT(ISNUMBER(G25))),AND(H25<>"",NOT(ISNUMBER(H25)))),"Precio no es número",IF(N(G25)+N(H25)<=0,"Falta precio","✓ OK"))))))))))) -> ✓ OK | M25: =IF(N25<>"W","",IF(TRIM(C25)<>"",TRIM(C25),IFERROR(LOOKUP(2,1/(N$9:N25="T"),D$9:D25),""))) -> REVOQUES | N25: =IF(TRIM(D25)="","",IF(AND(TRIM(E25)="",IFERROR(N(F25),1)=0,IFERROR(N(G25)+N(H25),1)=0),"T","W")) -> W | O25: =IF(M25="","",IF(COUNTIF(M$9:M25,M25)=1,MAX(O$8:O24)+1,""))
A26: =IF(N26="W",COUNTIF(N$9:N26,"W"),"") -> 18 | B26: Nivel 3 | C26: REVOQUES | D26: Revoque de mocheta en Pilares (mayor a 40 cm) | E26: ml | F26: =2.95*(1+2+1+1+1+1+2+1+2+2+1+1) -> 47.2 | G26: 40000 | H26: 26468 | I26: =IF(N26="W",IFERROR(N(G26)+N(H26),0),"") -> 66468 | J26: =IF(N26="W",IFERROR(N(F26)*I26,0),"") -> 3137289.6 | L26: =IF(N26="","",IF(N26="T","Título de capítulo",IF(OR(ISERROR(F26),ISERROR(G26),ISERROR(H26)),"Error en fórmula: pegá como valores",IF(AND(B26="",$C$6=""),"Falta sector",IF(M26="","Falta capítulo",IF(TRIM(E26)="","Falta unidad",IF(NOT((COUNTIF(Listas!$A$2:$A$40,E26)+COUNTIF(Listas!$D$2:$D$60,E26)>0)),"Unidad no reconocida",IF(AND(F26<>"",NOT(ISNUMBER(F26))),"Cantidad no es número",IF(N(F26)<=0,"Falta cantidad",IF(OR(AND(G26<>"",NOT(ISNUMBER(G26))),AND(H26<>"",NOT(ISNUMBER(H26)))),"Precio no es número",IF(N(G26)+N(H26)<=0,"Falta precio","✓ OK"))))))))))) -> ✓ OK | M26: =IF(N26<>"W","",IF(TRIM(C26)<>"",TRIM(C26),IFERROR(LOOKUP(2,1/(N$9:N26="T"),D$9:D26),""))) -> REVOQUES | N26: =IF(TRIM(D26)="","",IF(AND(TRIM(E26)="",IFERROR(N(F26),1)=0,IFERROR(N(G26)+N(H26),1)=0),"T","W")) -> W | O26: =IF(M26="","",IF(COUNTIF(M$9:M26,M26)=1,MAX(O$8:O25)+1,""))
A27: =IF(N27="W",COUNTIF(N$9:N27,"W"),"") -> 19 | B27: Nivel 3 | C27: REVOQUES | D27: Demolición de revoque viejo en pilares (menor a 40cm) | E27: ml | F27: 79.65 | G27: =0.4*10000 -> 4000 | H27: 0 | I27: =IF(N27="W",IFERROR(N(G27)+N(H27),0),"") -> 4000 | J27: =IF(N27="W",IFERROR(N(F27)*I27,0),"") -> 318600 | L27: =IF(N27="","",IF(N27="T","Título de capítulo",IF(OR(ISERROR(F27),ISERROR(G27),ISERROR(H27)),"Error en fórmula: pegá como valores",IF(AND(B27="",$C$6=""),"Falta sector",IF(M27="","Falta capítulo",IF(TRIM(E27)="","Falta unidad",IF(NOT((COUNTIF(Listas!$A$2:$A$40,E27)+COUNTIF(Listas!$D$2:$D$60,E27)>0)),"Unidad no reconocida",IF(AND(F27<>"",NOT(ISNUMBER(F27))),"Cantidad no es número",IF(N(F27)<=0,"Falta cantidad",IF(OR(AND(G27<>"",NOT(ISNUMBER(G27))),AND(H27<>"",NOT(ISNUMBER(H27)))),"Precio no es número",IF(N(G27)+N(H27)<=0,"Falta precio","✓ OK"))))))))))) -> ✓ OK | M27: =IF(N27<>"W","",IF(TRIM(C27)<>"",TRIM(C27),IFERROR(LOOKUP(2,1/(N$9:N27="T"),D$9:D27),""))) -> REVOQUES | N27: =IF(TRIM(D27)="","",IF(AND(TRIM(E27)="",IFERROR(N(F27),1)=0,IFERROR(N(G27)+N(H27),1)=0),"T","W")) -> W | O27: =IF(M27="","",IF(COUNTIF(M$9:M27,M27)=1,MAX(O$8:O26)+1,""))
A28: =IF(N28="W",COUNTIF(N$9:N28,"W"),"") -> 20 | B28: Nivel 3 | C28: REVOQUES | D28: Demolición de revoque viejo en pilares (mayor a 40cm) | E28: ml | F28: 47.2 | G28: =0.8*10000 -> 8000 | H28: 0 | I28: =IF(N28="W",IFERROR(N(G28)+N(H28),0),"") -> 8000 | J28: =IF(N28="W",IFERROR(N(F28)*I28,0),"") -> 377600 | L28: =IF(N28="","",IF(N28="T","Título de capítulo",IF(OR(ISERROR(F28),ISERROR(G28),ISERROR(H28)),"Error en fórmula: pegá como valores",IF(AND(B28="",$C$6=""),"Falta sector",IF(M28="","Falta capítulo",IF(TRIM(E28)="","Falta unidad",IF(NOT((COUNTIF(Listas!$A$2:$A$40,E28)+COUNTIF(Listas!$D$2:$D$60,E28)>0)),"Unidad no reconocida",IF(AND(F28<>"",NOT(ISNUMBER(F28))),"Cantidad no es número",IF(N(F28)<=0,"Falta cantidad",IF(OR(AND(G28<>"",NOT(ISNUMBER(G28))),AND(H28<>"",NOT(ISNUMBER(H28)))),"Precio no es número",IF(N(G28)+N(H28)<=0,"Falta precio","✓ OK"))))))))))) -> ✓ OK | M28: =IF(N28<>"W","",IF(TRIM(C28)<>"",TRIM(C28),IFERROR(LOOKUP(2,1/(N$9:N28="T"),D$9:D28),""))) -> REVOQUES | N28: =IF(TRIM(D28)="","",IF(AND(TRIM(E28)="",IFERROR(N(F28),1)=0,IFERROR(N(G28)+N(H28),1)=0),"T","W")) -> W | O28: =IF(M28="","",IF(COUNTIF(M$9:M28,M28)=1,MAX(O$8:O27)+1,""))
A29: =IF(N29="W",COUNTIF(N$9:N29,"W"),"") -> 21 | B29: Nivel 3 | C29: REVOQUES | D29: Revoque de muros externos lado fachada | E29: m2 | F29: =21.96*3 -> 65.88 | G29: 65000 | H29: 35000 | I29: =IF(N29="W",IFERROR(N(G29)+N(H29),0),"") -> 100000 | J29: =IF(N29="W",IFERROR(N(F29)*I29,0),"") -> 6588000 | L29: =IF(N29="","",IF(N29="T","Título de capítulo",IF(OR(ISERROR(F29),ISERROR(G29),ISERROR(H29)),"Error en fórmula: pegá como valores",IF(AND(B29="",$C$6=""),"Falta sector",IF(M29="","Falta capítulo",IF(TRIM(E29)="","Falta unidad",IF(NOT((COUNTIF(Listas!$A$2:$A$40,E29)+COUNTIF(Listas!$D$2:$D$60,E29)>0)),"Unidad no reconocida",IF(AND(F29<>"",NOT(ISNUMBER(F29))),"Cantidad no es número",IF(N(F29)<=0,"Falta cantidad",IF(OR(AND(G29<>"",NOT(ISNUMBER(G29))),AND(H29<>"",NOT(ISNUMBER(H29)))),"Precio no es número",IF(N(G29)+N(H29)<=0,"Falta precio","✓ OK"))))))))))) -> ✓ OK | M29: =IF(N29<>"W","",IF(TRIM(C29)<>"",TRIM(C29),IFERROR(LOOKUP(2,1/(N$9:N29="T"),D$9:D29),""))) -> REVOQUES | N29: =IF(TRIM(D29)="","",IF(AND(TRIM(E29)="",IFERROR(N(F29),1)=0,IFERROR(N(G29)+N(H29),1)=0),"T","W")) -> W | O29: =IF(M29="","",IF(COUNTIF(M$9:M29,M29)=1,MAX(O$8:O28)+1,""))
A30: =IF(N30="W",COUNTIF(N$9:N30,"W"),"") -> 22 | B30: Nivel 3 | C30: REVOQUES | D30: Prolijado de escalera de hormigón de paso a edificio Neider | E30: gl | F30: 1 | G30: 1500000 | H30: =13234*84.88 -> 1123301.9 | I30: =IF(N30="W",IFERROR(N(G30)+N(H30),0),"") -> 2623301.9 | J30: =IF(N30="W",IFERROR(N(F30)*I30,0),"") -> 2623301.9 | L30: =IF(N30="","",IF(N30="T","Título de capítulo",IF(OR(ISERROR(F30),ISERROR(G30),ISERROR(H30)),"Error en fórmula: pegá como valores",IF(AND(B30="",$C$6=""),"Falta sector",IF(M30="","Falta capítulo",IF(TRIM(E30)="","Falta unidad",IF(NOT((COUNTIF(Listas!$A$2:$A$40,E30)+COUNTIF(Listas!$D$2:$D$60,E30)>0)),"Unidad no reconocida",IF(AND(F30<>"",NOT(ISNUMBER(F30))),"Cantidad no es número",IF(N(F30)<=0,"Falta cantidad",IF(OR(AND(G30<>"",NOT(ISNUMBER(G30))),AND(H30<>"",NOT(ISNUMBER(H30)))),"Precio no es número",IF(N(G30)+N(H30)<=0,"Falta precio","✓ OK"))))))))))) -> ✓ OK | M30: =IF(N30<>"W","",IF(TRIM(C30)<>"",TRIM(C30),IFERROR(LOOKUP(2,1/(N$9:N30="T"),D$9:D30),""))) -> REVOQUES | N30: =IF(TRIM(D30)="","",IF(AND(TRIM(E30)="",IFERROR(N(F30),1)=0,IFERROR(N(G30)+N(H30),1)=0),"T","W")) -> W | O30: =IF(M30="","",IF(COUNTIF(M$9:M30,M30)=1,MAX(O$8:O29)+1,""))
A31: =IF(N31="W",COUNTIF(N$9:N31,"W"),"") -> 23 | B31: Nivel 3 | C31: REVOQUES | D31: Buña en revoque exterior de fachada | E31: ml | F31: =21.96*2 -> 43.92 | G31: 20000 | H31: 0 | I31: =IF(N31="W",IFERROR(N(G31)+N(H31),0),"") -> 20000 | J31: =IF(N31="W",IFERROR(N(F31)*I31,0),"") -> 878400 | L31: =IF(N31="","",IF(N31="T","Título de capítulo",IF(OR(ISERROR(F31),ISERROR(G31),ISERROR(H31)),"Error en fórmula: pegá como valores",IF(AND(B31="",$C$6=""),"Falta sector",IF(M31="","Falta capítulo",IF(TRIM(E31)="","Falta unidad",IF(NOT((COUNTIF(Listas!$A$2:$A$40,E31)+COUNTIF(Listas!$D$2:$D$60,E31)>0)),"Unidad no reconocida",IF(AND(F31<>"",NOT(ISNUMBER(F31))),"Cantidad no es número",IF(N(F31)<=0,"Falta cantidad",IF(OR(AND(G31<>"",NOT(ISNUMBER(G31))),AND(H31<>"",NOT(ISNUMBER(H31)))),"Precio no es número",IF(N(G31)+N(H31)<=0,"Falta precio","✓ OK"))))))))))) -> ✓ OK | M31: =IF(N31<>"W","",IF(TRIM(C31)<>"",TRIM(C31),IFERROR(LOOKUP(2,1/(N$9:N31="T"),D$9:D31),""))) -> REVOQUES | N31: =IF(TRIM(D31)="","",IF(AND(TRIM(E31)="",IFERROR(N(F31),1)=0,IFERROR(N(G31)+N(H31),1)=0),"T","W")) -> W | O31: =IF(M31="","",IF(COUNTIF(M$9:M31,M31)=1,MAX(O$8:O30)+1,""))
A32: =IF(N32="W",COUNTIF(N$9:N32,"W"),"") -> 24 | B32: Nivel 3 | C32: REVOQUES | D32: Metal desplegado en unión de Hormigón con mampostería | E32: ml | F32: =19.5*2*2+3*4*2+(3.68*2*2)+5.58*2*2+6.49*2*2+3*6+3*7 -> 204 | G32: 20000 | H32: 35000 | I32: =IF(N32="W",IFERROR(N(G32)+N(H32),0),"") -> 55000 | J32: =IF(N32="W",IFERROR(N(F32)*I32,0),"") -> 11220000 | L32: =IF(N32="","",IF(N32="T","Título de capítulo",IF(OR(ISERROR(F32),ISERROR(G32),ISERROR(H32)),"Error en fórmula: pegá como valores",IF(AND(B32="",$C$6=""),"Falta sector",IF(M32="","Falta capítulo",IF(TRIM(E32)="","Falta unidad",IF(NOT((COUNTIF(Listas!$A$2:$A$40,E32)+COUNTIF(Listas!$D$2:$D$60,E32)>0)),"Unidad no reconocida",IF(AND(F32<>"",NOT(ISNUMBER(F32))),"Cantidad no es número",IF(N(F32)<=0,"Falta cantidad",IF(OR(AND(G32<>"",NOT(ISNUMBER(G32))),AND(H32<>"",NOT(ISNUMBER(H32)))),"Precio no es número",IF(N(G32)+N(H32)<=0,"Falta precio","✓ OK"))))))))))) -> ✓ OK | M32: =IF(N32<>"W","",IF(TRIM(C32)<>"",TRIM(C32),IFERROR(LOOKUP(2,1/(N$9:N32="T"),D$9:D32),""))) -> REVOQUES | N32: =IF(TRIM(D32)="","",IF(AND(TRIM(E32)="",IFERROR(N(F32),1)=0,IFERROR(N(G32)+N(H32),1)=0),"T","W")) -> W | O32: =IF(M32="","",IF(COUNTIF(M$9:M32,M32)=1,MAX(O$8:O31)+1,""))
A33: =IF(N33="W",COUNTIF(N$9:N33,"W"),"") -> 25 | B33: Nivel 3 | C33: CONTRAPISOS Y CARPETAS | D33: Contrapiso | E33: m2 | F33: =5.15*3.4+2.15*3.4+109.13 -> 133.95 | G33: =35000+13000 -> 48000 | H33: 17500 | I33: =IF(N33="W",IFERROR(N(G33)+N(H33),0),"") -> 65500 | J33: =IF(N33="W",IFERROR(N(F33)*I33,0),"") -> 8773725 | L33: =IF(N33="","",IF(N33="T","Título de capítulo",IF(OR(ISERROR(F33),ISERROR(G33),ISERROR(H33)),"Error en fórmula: pegá como valores",IF(AND(B33="",$C$6=""),"Falta sector",IF(M33="","Falta capítulo",IF(TRIM(E33)="","Falta unidad",IF(NOT((COUNTIF(Listas!$A$2:$A$40,E33)+COUNTIF(Listas!$D$2:$D$60,E33)>0)),"Unidad no reconocida",IF(AND(F33<>"",NOT(ISNUMBER(F33))),"Cantidad no es número",IF(N(F33)<=0,"Falta cantidad",IF(OR(AND(G33<>"",NOT(ISNUMBER(G33))),AND(H33<>"",NOT(ISNUMBER(H33)))),"Precio no es número",IF(N(G33)+N(H33)<=0,"Falta precio","✓ OK"))))))))))) -> ✓ OK | M33: =IF(N33<>"W","",IF(TRIM(C33)<>"",TRIM(C33),IFERROR(LOOKUP(2,1/(N$9:N33="T"),D$9:D33),""))) -> CONTRAPISOS Y CARPETAS | N33: =IF(TRIM(D33)="","",IF(AND(TRIM(E33)="",IFERROR(N(F33),1)=0,IFERROR(N(G33)+N(H33),1)=0),"T","W")) -> W | O33: =IF(M33="","",IF(COUNTIF(M$9:M33,M33)=1,MAX(O$8:O32)+1,"")) -> 4
A34: =IF(N34="W",COUNTIF(N$9:N34,"W"),"") -> 26 | B34: Nivel 3 | C34: CONTRAPISOS Y CARPETAS | D34: Carpeta con hidrófugo | E34: m2 | F34: 133.95 | G34: 40000 | H34: 20500 | I34: =IF(N34="W",IFERROR(N(G34)+N(H34),0),"") -> 60500 | J34: =IF(N34="W",IFERROR(N(F34)*I34,0),"") -> 8103975 | L34: =IF(N34="","",IF(N34="T","Título de capítulo",IF(OR(ISERROR(F34),ISERROR(G34),ISERROR(H34)),"Error en fórmula: pegá como valores",IF(AND(B34="",$C$6=""),"Falta sector",IF(M34="","Falta capítulo",IF(TRIM(E34)="","Falta unidad",IF(NOT((COUNTIF(Listas!$A$2:$A$40,E34)+COUNTIF(Listas!$D$2:$D$60,E34)>0)),"Unidad no reconocida",IF(AND(F34<>"",NOT(ISNUMBER(F34))),"Cantidad no es número",IF(N(F34)<=0,"Falta cantidad",IF(OR(AND(G34<>"",NOT(ISNUMBER(G34))),AND(H34<>"",NOT(ISNUMBER(H34)))),"Precio no es número",IF(N(G34)+N(H34)<=0,"Falta precio","✓ OK"))))))))))) -> ✓ OK | M34: =IF(N34<>"W","",IF(TRIM(C34)<>"",TRIM(C34),IFERROR(LOOKUP(2,1/(N$9:N34="T"),D$9:D34),""))) -> CONTRAPISOS Y CARPETAS | N34: =IF(TRIM(D34)="","",IF(AND(TRIM(E34)="",IFERROR(N(F34),1)=0,IFERROR(N(G34)+N(H34),1)=0),"T","W")) -> W | O34: =IF(M34="","",IF(COUNTIF(M$9:M34,M34)=1,MAX(O$8:O33)+1,""))
A35: =IF(N35="W",COUNTIF(N$9:N35,"W"),"") -> 27 | B35: Nivel 3 | C35: AYUDA DE GREMIOS | D35: Acarreo y retiro de escombros | E35: m3 | F35: 48.41 | G35: 233333 | H35: 0 | I35: =IF(N35="W",IFERROR(N(G35)+N(H35),0),"") -> 233333 | J35: =IF(N35="W",IFERROR(N(F35)*I35,0),"") -> 11295651 | L35: =IF(N35="","",IF(N35="T","Título de capítulo",IF(OR(ISERROR(F35),ISERROR(G35),ISERROR(H35)),"Error en fórmula: pegá como valores",IF(AND(B35="",$C$6=""),"Falta sector",IF(M35="","Falta capítulo",IF(TRIM(E35)="","Falta unidad",IF(NOT((COUNTIF(Listas!$A$2:$A$40,E35)+COUNTIF(Listas!$D$2:$D$60,E35)>0)),"Unidad no reconocida",IF(AND(F35<>"",NOT(ISNUMBER(F35))),"Cantidad no es número",IF(N(F35)<=0,"Falta cantidad",IF(OR(AND(G35<>"",NOT(ISNUMBER(G35))),AND(H35<>"",NOT(ISNUMBER(H35)))),"Precio no es número",IF(N(G35)+N(H35)<=0,"Falta precio","✓ OK"))))))))))) -> ✓ OK | M35: =IF(N35<>"W","",IF(TRIM(C35)<>"",TRIM(C35),IFERROR(LOOKUP(2,1/(N$9:N35="T"),D$9:D35),""))) -> AYUDA DE GREMIOS | N35: =IF(TRIM(D35)="","",IF(AND(TRIM(E35)="",IFERROR(N(F35),1)=0,IFERROR(N(G35)+N(H35),1)=0),"T","W")) -> W | O35: =IF(M35="","",IF(COUNTIF(M$9:M35,M35)=1,MAX(O$8:O34)+1,"")) -> 5
A36: =IF(N36="W",COUNTIF(N$9:N36,"W"),"") -> 28 | B36: Nivel 3 | C36: AYUDA DE GREMIOS | D36: Acarreo y transporte de sobrantes basuras y otros | E36: viaje | F36: 1 | G36: 440000 | H36: 500000 | I36: =IF(N36="W",IFERROR(N(G36)+N(H36),0),"") -> 940000 | J36: =IF(N36="W",IFERROR(N(F36)*I36,0),"") -> 940000 | L36: =IF(N36="","",IF(N36="T","Título de capítulo",IF(OR(ISERROR(F36),ISERROR(G36),ISERROR(H36)),"Error en fórmula: pegá como valores",IF(AND(B36="",$C$6=""),"Falta sector",IF(M36="","Falta capítulo",IF(TRIM(E36)="","Falta unidad",IF(NOT((COUNTIF(Listas!$A$2:$A$40,E36)+COUNTIF(Listas!$D$2:$D$60,E36)>0)),"Unidad no reconocida",IF(AND(F36<>"",NOT(ISNUMBER(F36))),"Cantidad no es número",IF(N(F36)<=0,"Falta cantidad",IF(OR(AND(G36<>"",NOT(ISNUMBER(G36))),AND(H36<>"",NOT(ISNUMBER(H36)))),"Precio no es número",IF(N(G36)+N(H36)<=0,"Falta precio","✓ OK"))))))))))) -> ✓ OK | M36: =IF(N36<>"W","",IF(TRIM(C36)<>"",TRIM(C36),IFERROR(LOOKUP(2,1/(N$9:N36="T"),D$9:D36),""))) -> AYUDA DE GREMIOS | N36: =IF(TRIM(D36)="","",IF(AND(TRIM(E36)="",IFERROR(N(F36),1)=0,IFERROR(N(G36)+N(H36),1)=0),"T","W")) -> W | O36: =IF(M36="","",IF(COUNTIF(M$9:M36,M36)=1,MAX(O$8:O35)+1,""))
A37: =IF(N37="W",COUNTIF(N$9:N37,"W"),"") -> 29 | B37: Nivel 3 | C37: AYUDA DE GREMIOS | D37: Alquiler de andamios | E37: gl | F37: 1 | G37: 0 | H37: 1800000 | I37: =IF(N37="W",IFERROR(N(G37)+N(H37),0),"") -> 1800000 | J37: =IF(N37="W",IFERROR(N(F37)*I37,0),"") -> 1800000 | L37: =IF(N37="","",IF(N37="T","Título de capítulo",IF(OR(ISERROR(F37),ISERROR(G37),ISERROR(H37)),"Error en fórmula: pegá como valores",IF(AND(B37="",$C$6=""),"Falta sector",IF(M37="","Falta capítulo",IF(TRIM(E37)="","Falta unidad",IF(NOT((COUNTIF(Listas!$A$2:$A$40,E37)+COUNTIF(Listas!$D$2:$D$60,E37)>0)),"Unidad no reconocida",IF(AND(F37<>"",NOT(ISNUMBER(F37))),"Cantidad no es número",IF(N(F37)<=0,"Falta cantidad",IF(OR(AND(G37<>"",NOT(ISNUMBER(G37))),AND(H37<>"",NOT(ISNUMBER(H37)))),"Precio no es número",IF(N(G37)+N(H37)<=0,"Falta precio","✓ OK"))))))))))) -> ✓ OK | M37: =IF(N37<>"W","",IF(TRIM(C37)<>"",TRIM(C37),IFERROR(LOOKUP(2,1/(N$9:N37="T"),D$9:D37),""))) -> AYUDA DE GREMIOS | N37: =IF(TRIM(D37)="","",IF(AND(TRIM(E37)="",IFERROR(N(F37),1)=0,IFERROR(N(G37)+N(H37),1)=0),"T","W")) -> W | O37: =IF(M37="","",IF(COUNTIF(M$9:M37,M37)=1,MAX(O$8:O36)+1,""))
A38: =IF(N38="W",COUNTIF(N$9:N38,"W"),"") | I38: =IF(N38="W",IFERROR(N(G38)+N(H38),0),"") | J38: =IF(N38="W",IFERROR(N(F38)*I38,0),"") | L38: =IF(N38="","",IF(N38="T","Título de capítulo",IF(OR(ISERROR(F38),ISERROR(G38),ISERROR(H38)),"Error en fórmula: pegá como valores",IF(AND(B38="",$C$6=""),"Falta sector",IF(M38="","Falta capítulo",IF(TRIM(E38)="","Falta unidad",IF(NOT((COUNTIF(Listas!$A$2:$A$40,E38)+COUNTIF(Listas!$D$2:$D$60,E38)>0)),"Unidad no reconocida",IF(AND(F38<>"",NOT(ISNUMBER(F38))),"Cantidad no es número",IF(N(F38)<=0,"Falta cantidad",IF(OR(AND(G38<>"",NOT(ISNUMBER(G38))),AND(H38<>"",NOT(ISNUMBER(H38)))),"Precio no es número",IF(N(G38)+N(H38)<=0,"Falta precio","✓ OK"))))))))))) | M38: =IF(N38<>"W","",IF(TRIM(C38)<>"",TRIM(C38),IFERROR(LOOKUP(2,1/(N$9:N38="T"),D$9:D38),""))) | N38: =IF(TRIM(D38)="","",IF(AND(TRIM(E38)="",IFERROR(N(F38),1)=0,IFERROR(N(G38)+N(H38),1)=0),"T","W")) | O38: =IF(M38="","",IF(COUNTIF(M$9:M38,M38)=1,MAX(O$8:O37)+1,""))
A39: =IF(N39="W",COUNTIF(N$9:N39,"W"),"") | I39: =IF(N39="W",IFERROR(N(G39)+N(H39),0),"") | J39: =IF(N39="W",IFERROR(N(F39)*I39,0),"") | L39: =IF(N39="","",IF(N39="T","Título de capítulo",IF(OR(ISERROR(F39),ISERROR(G39),ISERROR(H39)),"Error en fórmula: pegá como valores",IF(AND(B39="",$C$6=""),"Falta sector",IF(M39="","Falta capítulo",IF(TRIM(E39)="","Falta unidad",IF(NOT((COUNTIF(Listas!$A$2:$A$40,E39)+COUNTIF(Listas!$D$2:$D$60,E39)>0)),"Unidad no reconocida",IF(AND(F39<>"",NOT(ISNUMBER(F39))),"Cantidad no es número",IF(N(F39)<=0,"Falta cantidad",IF(OR(AND(G39<>"",NOT(ISNUMBER(G39))),AND(H39<>"",NOT(ISNUMBER(H39)))),"Precio no es número",IF(N(G39)+N(H39)<=0,"Falta precio","✓ OK"))))))))))) | M39: =IF(N39<>"W","",IF(TRIM(C39)<>"",TRIM(C39),IFERROR(LOOKUP(2,1/(N$9:N39="T"),D$9:D39),""))) | N39: =IF(TRIM(D39)="","",IF(AND(TRIM(E39)="",IFERROR(N(F39),1)=0,IFERROR(N(G39)+N(H39),1)=0),"T","W")) | O39: =IF(M39="","",IF(COUNTIF(M$9:M39,M39)=1,MAX(O$8:O38)+1,""))
A40: =IF(N40="W",COUNTIF(N$9:N40,"W"),"") | I40: =IF(N40="W",IFERROR(N(G40)+N(H40),0),"") | J40: =IF(N40="W",IFERROR(N(F40)*I40,0),"") | L40: =IF(N40="","",IF(N40="T","Título de capítulo",IF(OR(ISERROR(F40),ISERROR(G40),ISERROR(H40)),"Error en fórmula: pegá como valores",IF(AND(B40="",$C$6=""),"Falta sector",IF(M40="","Falta capítulo",IF(TRIM(E40)="","Falta unidad",IF(NOT((COUNTIF(Listas!$A$2:$A$40,E40)+COUNTIF(Listas!$D$2:$D$60,E40)>0)),"Unidad no reconocida",IF(AND(F40<>"",NOT(ISNUMBER(F40))),"Cantidad no es número",IF(N(F40)<=0,"Falta cantidad",IF(OR(AND(G40<>"",NOT(ISNUMBER(G40))),AND(H40<>"",NOT(ISNUMBER(H40)))),"Precio no es número",IF(N(G40)+N(H40)<=0,"Falta precio","✓ OK"))))))))))) | M40: =IF(N40<>"W","",IF(TRIM(C40)<>"",TRIM(C40),IFERROR(LOOKUP(2,1/(N$9:N40="T"),D$9:D40),""))) | N40: =IF(TRIM(D40)="","",IF(AND(TRIM(E40)="",IFERROR(N(F40),1)=0,IFERROR(N(G40)+N(H40),1)=0),"T","W")) | O40: =IF(M40="","",IF(COUNTIF(M$9:M40,M40)=1,MAX(O$8:O39)+1,""))
A41: =IF(N41="W",COUNTIF(N$9:N41,"W"),"") | I41: =IF(N41="W",IFERROR(N(G41)+N(H41),0),"") | J41: =IF(N41="W",IFERROR(N(F41)*I41,0),"") | L41: =IF(N41="","",IF(N41="T","Título de capítulo",IF(OR(ISERROR(F41),ISERROR(G41),ISERROR(H41)),"Error en fórmula: pegá como valores",IF(AND(B41="",$C$6=""),"Falta sector",IF(M41="","Falta capítulo",IF(TRIM(E41)="","Falta unidad",IF(NOT((COUNTIF(Listas!$A$2:$A$40,E41)+COUNTIF(Listas!$D$2:$D$60,E41)>0)),"Unidad no reconocida",IF(AND(F41<>"",NOT(ISNUMBER(F41))),"Cantidad no es número",IF(N(F41)<=0,"Falta cantidad",IF(OR(AND(G41<>"",NOT(ISNUMBER(G41))),AND(H41<>"",NOT(ISNUMBER(H41)))),"Precio no es número",IF(N(G41)+N(H41)<=0,"Falta precio","✓ OK"))))))))))) | M41: =IF(N41<>"W","",IF(TRIM(C41)<>"",TRIM(C41),IFERROR(LOOKUP(2,1/(N$9:N41="T"),D$9:D41),""))) | N41: =IF(TRIM(D41)="","",IF(AND(TRIM(E41)="",IFERROR(N(F41),1)=0,IFERROR(N(G41)+N(H41),1)=0),"T","W")) | O41: =IF(M41="","",IF(COUNTIF(M$9:M41,M41)=1,MAX(O$8:O40)+1,""))
A42: =IF(N42="W",COUNTIF(N$9:N42,"W"),"") | I42: =IF(N42="W",IFERROR(N(G42)+N(H42),0),"") | J42: =IF(N42="W",IFERROR(N(F42)*I42,0),"") | L42: =IF(N42="","",IF(N42="T","Título de capítulo",IF(OR(ISERROR(F42),ISERROR(G42),ISERROR(H42)),"Error en fórmula: pegá como valores",IF(AND(B42="",$C$6=""),"Falta sector",IF(M42="","Falta capítulo",IF(TRIM(E42)="","Falta unidad",IF(NOT((COUNTIF(Listas!$A$2:$A$40,E42)+COUNTIF(Listas!$D$2:$D$60,E42)>0)),"Unidad no reconocida",IF(AND(F42<>"",NOT(ISNUMBER(F42))),"Cantidad no es número",IF(N(F42)<=0,"Falta cantidad",IF(OR(AND(G42<>"",NOT(ISNUMBER(G42))),AND(H42<>"",NOT(ISNUMBER(H42)))),"Precio no es número",IF(N(G42)+N(H42)<=0,"Falta precio","✓ OK"))))))))))) | M42: =IF(N42<>"W","",IF(TRIM(C42)<>"",TRIM(C42),IFERROR(LOOKUP(2,1/(N$9:N42="T"),D$9:D42),""))) | N42: =IF(TRIM(D42)="","",IF(AND(TRIM(E42)="",IFERROR(N(F42),1)=0,IFERROR(N(G42)+N(H42),1)=0),"T","W")) | O42: =IF(M42="","",IF(COUNTIF(M$9:M42,M42)=1,MAX(O$8:O41)+1,""))
...

Sheet Resumen
B1: RESUMEN POR CAPÍTULO
B2: =Presupuesto!C4&" · "&Presupuesto!C5 -> EDIFICIO ORQUÍDEAS · Presupuesto 68 · Nivel 3
B4: Capítulo | C4: Trabajos | D4: Parcial ₲ | E4: %
B5: =IFERROR(INDEX(Presupuesto!$M$9:$M$1008,MATCH(1,Presupuesto!$O$9:$O$1008,0)),"") -> PRELIMINARES | C5: =IF(B5="","",COUNTIF(Presupuesto!$M$9:$M$1008,B5)) -> 2 | D5: =IF(B5="","",SUMIF(Presupuesto!$M$9:$M$1008,B5,Presupuesto!$J$9:$J$1008)) -> 3431500 | E5: =IF(OR(B5="",$D$45=0),"",D5/$D$45) -> 0.014438886
B6: =IFERROR(INDEX(Presupuesto!$M$9:$M$1008,MATCH(2,Presupuesto!$O$9:$O$1008,0)),"") -> MAMPOSTERÍA | C6: =IF(B6="","",COUNTIF(Presupuesto!$M$9:$M$1008,B6)) -> 5 | D6: =IF(B6="","",SUMIF(Presupuesto!$M$9:$M$1008,B6,Presupuesto!$J$9:$J$1008)) -> 30603851 | E6: =IF(OR(B6="",$D$45=0),"",D6/$D$45) -> 0.12877328
B7: =IFERROR(INDEX(Presupuesto!$M$9:$M$1008,MATCH(3,Presupuesto!$O$9:$O$1008,0)),"") -> REVOQUES | C7: =IF(B7="","",COUNTIF(Presupuesto!$M$9:$M$1008,B7)) -> 17 | D7: =IF(B7="","",SUMIF(Presupuesto!$M$9:$M$1008,B7,Presupuesto!$J$9:$J$1008)) -> 1.7270814e+08 | E7: =IF(OR(B7="",$D$45=0),"",D7/$D$45) -> 0.72671226
B8: =IFERROR(INDEX(Presupuesto!$M$9:$M$1008,MATCH(4,Presupuesto!$O$9:$O$1008,0)),"") -> CONTRAPISOS Y CARPETAS | C8: =IF(B8="","",COUNTIF(Presupuesto!$M$9:$M$1008,B8)) -> 2 | D8: =IF(B8="","",SUMIF(Presupuesto!$M$9:$M$1008,B8,Presupuesto!$J$9:$J$1008)) -> 16877700 | E8: =IF(OR(B8="",$D$45=0),"",D8/$D$45) -> 0.071017102
B9: =IFERROR(INDEX(Presupuesto!$M$9:$M$1008,MATCH(5,Presupuesto!$O$9:$O$1008,0)),"") -> AYUDA DE GREMIOS | C9: =IF(B9="","",COUNTIF(Presupuesto!$M$9:$M$1008,B9)) -> 3 | D9: =IF(B9="","",SUMIF(Presupuesto!$M$9:$M$1008,B9,Presupuesto!$J$9:$J$1008)) -> 14035651 | E9: =IF(OR(B9="",$D$45=0),"",D9/$D$45) -> 0.059058475
B10: =IFERROR(INDEX(Presupuesto!$M$9:$M$1008,MATCH(6,Presupuesto!$O$9:$O$1008,0)),"") | C10: =IF(B10="","",COUNTIF(Presupuesto!$M$9:$M$1008,B10)) | D10: =IF(B10="","",SUMIF(Presupuesto!$M$9:$M$1008,B10,Presupuesto!$J$9:$J$1008)) | E10: =IF(OR(B10="",$D$45=0),"",D10/$D$45)
B11: =IFERROR(INDEX(Presupuesto!$M$9:$M$1008,MATCH(7,Presupuesto!$O$9:$O$1008,0)),"") | C11: =IF(B11="","",COUNTIF(Presupuesto!$M$9:$M$1008,B11)) | D11: =IF(B11="","",SUMIF(Presupuesto!$M$9:$M$1008,B11,Presupuesto!$J$9:$J$1008)) | E11: =IF(OR(B11="",$D$45=0),"",D11/$D$45)
B12: =IFERROR(INDEX(Presupuesto!$M$9:$M$1008,MATCH(8,Presupuesto!$O$9:$O$1008,0)),"") | C12: =IF(B12="","",COUNTIF(Presupuesto!$M$9:$M$1008,B12)) | D12: =IF(B12="","",SUMIF(Presupuesto!$M$9:$M$1008,B12,Presupuesto!$J$9:$J$1008)) | E12: =IF(OR(B12="",$D$45=0),"",D12/$D$45)
B13: =IFERROR(INDEX(Presupuesto!$M$9:$M$1008,MATCH(9,Presupuesto!$O$9:$O$1008,0)),"") | C13: =IF(B13="","",COUNTIF(Presupuesto!$M$9:$M$1008,B13)) | D13: =IF(B13="","",SUMIF(Presupuesto!$M$9:$M$1008,B13,Presupuesto!$J$9:$J$1008)) | E13: =IF(OR(B13="",$D$45=0),"",D13/$D$45)
B14: =IFERROR(INDEX(Presupuesto!$M$9:$M$1008,MATCH(10,Presupuesto!$O$9:$O$1008,0)),"") | C14: =IF(B14="","",COUNTIF(Presupuesto!$M$9:$M$1008,B14)) | D14: =IF(B14="","",SUMIF(Presupuesto!$M$9:$M$1008,B14,Presupuesto!$J$9:$J$1008)) | E14: =IF(OR(B14="",$D$45=0),"",D14/$D$45)
B15: =IFERROR(INDEX(Presupuesto!$M$9:$M$1008,MATCH(11,Presupuesto!$O$9:$O$1008,0)),"") | C15: =IF(B15="","",COUNTIF(Presupuesto!$M$9:$M$1008,B15)) | D15: =IF(B15="","",SUMIF(Presupuesto!$M$9:$M$1008,B15,Presupuesto!$J$9:$J$1008)) | E15: =IF(OR(B15="",$D$45=0),"",D15/$D$45)
B16: =IFERROR(INDEX(Presupuesto!$M$9:$M$1008,MATCH(12,Presupuesto!$O$9:$O$1008,0)),"") | C16: =IF(B16="","",COUNTIF(Presupuesto!$M$9:$M$1008,B16)) | D16: =IF(B16="","",SUMIF(Presupuesto!$M$9:$M$1008,B16,Presupuesto!$J$9:$J$1008)) | E16: =IF(OR(B16="",$D$45=0),"",D16/$D$45)
B17: =IFERROR(INDEX(Presupuesto!$M$9:$M$1008,MATCH(13,Presupuesto!$O$9:$O$1008,0)),"") | C17: =IF(B17="","",COUNTIF(Presupuesto!$M$9:$M$1008,B17)) | D17: =IF(B17="","",SUMIF(Presupuesto!$M$9:$M$1008,B17,Presupuesto!$J$9:$J$1008)) | E17: =IF(OR(B17="",$D$45=0),"",D17/$D$45)
B18: =IFERROR(INDEX(Presupuesto!$M$9:$M$1008,MATCH(14,Presupuesto!$O$9:$O$1008,0)),"") | C18: =IF(B18="","",COUNTIF(Presupuesto!$M$9:$M$1008,B18)) | D18: =IF(B18="","",SUMIF(Presupuesto!$M$9:$M$1008,B18,Presupuesto!$J$9:$J$1008)) | E18: =IF(OR(B18="",$D$45=0),"",D18/$D$45)
B19: =IFERROR(INDEX(Presupuesto!$M$9:$M$1008,MATCH(15,Presupuesto!$O$9:$O$1008,0)),"") | C19: =IF(B19="","",COUNTIF(Presupuesto!$M$9:$M$1008,B19)) | D19: =IF(B19="","",SUMIF(Presupuesto!$M$9:$M$1008,B19,Presupuesto!$J$9:$J$1008)) | E19: =IF(OR(B19="",$D$45=0),"",D19/$D$45)
B20: =IFERROR(INDEX(Presupuesto!$M$9:$M$1008,MATCH(16,Presupuesto!$O$9:$O$1008,0)),"") | C20: =IF(B20="","",COUNTIF(Presupuesto!$M$9:$M$1008,B20)) | D20: =IF(B20="","",SUMIF(Presupuesto!$M$9:$M$1008,B20,Presupuesto!$J$9:$J$1008)) | E20: =IF(OR(B20="",$D$45=0),"",D20/$D$45)
B21: =IFERROR(INDEX(Presupuesto!$M$9:$M$1008,MATCH(17,Presupuesto!$O$9:$O$1008,0)),"") | C21: =IF(B21="","",COUNTIF(Presupuesto!$M$9:$M$1008,B21)) | D21: =IF(B21="","",SUMIF(Presupuesto!$M$9:$M$1008,B21,Presupuesto!$J$9:$J$1008)) | E21: =IF(OR(B21="",$D$45=0),"",D21/$D$45)
B22: =IFERROR(INDEX(Presupuesto!$M$9:$M$1008,MATCH(18,Presupuesto!$O$9:$O$1008,0)),"") | C22: =IF(B22="","",COUNTIF(Presupuesto!$M$9:$M$1008,B22)) | D22: =IF(B22="","",SUMIF(Presupuesto!$M$9:$M$1008,B22,Presupuesto!$J$9:$J$1008)) | E22: =IF(OR(B22="",$D$45=0),"",D22/$D$45)
B23: =IFERROR(INDEX(Presupuesto!$M$9:$M$1008,MATCH(19,Presupuesto!$O$9:$O$1008,0)),"") | C23: =IF(B23="","",COUNTIF(Presupuesto!$M$9:$M$1008,B23)) | D23: =IF(B23="","",SUMIF(Presupuesto!$M$9:$M$1008,B23,Presupuesto!$J$9:$J$1008)) | E23: =IF(OR(B23="",$D$45=0),"",D23/$D$45)
B24: =IFERROR(INDEX(Presupuesto!$M$9:$M$1008,MATCH(20,Presupuesto!$O$9:$O$1008,0)),"") | C24: =IF(B24="","",COUNTIF(Presupuesto!$M$9:$M$1008,B24)) | D24: =IF(B24="","",SUMIF(Presupuesto!$M$9:$M$1008,B24,Presupuesto!$J$9:$J$1008)) | E24: =IF(OR(B24="",$D$45=0),"",D24/$D$45)
B25: =IFERROR(INDEX(Presupuesto!$M$9:$M$1008,MATCH(21,Presupuesto!$O$9:$O$1008,0)),"") | C25: =IF(B25="","",COUNTIF(Presupuesto!$M$9:$M$1008,B25)) | D25: =IF(B25="","",SUMIF(Presupuesto!$M$9:$M$1008,B25,Presupuesto!$J$9:$J$1008)) | E25: =IF(OR(B25="",$D$45=0),"",D25/$D$45)
B26: =IFERROR(INDEX(Presupuesto!$M$9:$M$1008,MATCH(22,Presupuesto!$O$9:$O$1008,0)),"") | C26: =IF(B26="","",COUNTIF(Presupuesto!$M$9:$M$1008,B26)) | D26: =IF(B26="","",SUMIF(Presupuesto!$M$9:$M$1008,B26,Presupuesto!$J$9:$J$1008)) | E26: =IF(OR(B26="",$D$45=0),"",D26/$D$45)
B27: =IFERROR(INDEX(Presupuesto!$M$9:$M$1008,MATCH(23,Presupuesto!$O$9:$O$1008,0)),"") | C27: =IF(B27="","",COUNTIF(Presupuesto!$M$9:$M$1008,B27)) | D27: =IF(B27="","",SUMIF(Presupuesto!$M$9:$M$1008,B27,Presupuesto!$J$9:$J$1008)) | E27: =IF(OR(B27="",$D$45=0),"",D27/$D$45)
B28: =IFERROR(INDEX(Presupuesto!$M$9:$M$1008,MATCH(24,Presupuesto!$O$9:$O$1008,0)),"") | C28: =IF(B28="","",COUNTIF(Presupuesto!$M$9:$M$1008,B28)) | D28: =IF(B28="","",SUMIF(Presupuesto!$M$9:$M$1008,B28,Presupuesto!$J$9:$J$1008)) | E28: =IF(OR(B28="",$D$45=0),"",D28/$D$45)
B29: =IFERROR(INDEX(Presupuesto!$M$9:$M$1008,MATCH(25,Presupuesto!$O$9:$O$1008,0)),"") | C29: =IF(B29="","",COUNTIF(Presupuesto!$M$9:$M$1008,B29)) | D29: =IF(B29="","",SUMIF(Presupuesto!$M$9:$M$1008,B29,Presupuesto!$J$9:$J$1008)) | E29: =IF(OR(B29="",$D$45=0),"",D29/$D$45)
B30: =IFERROR(INDEX(Presupuesto!$M$9:$M$1008,MATCH(26,Presupuesto!$O$9:$O$1008,0)),"") | C30: =IF(B30="","",COUNTIF(Presupuesto!$M$9:$M$1008,B30)) | D30: =IF(B30="","",SUMIF(Presupuesto!$M$9:$M$1008,B30,Presupuesto!$J$9:$J$1008)) | E30: =IF(OR(B30="",$D$45=0),"",D30/$D$45)
B31: =IFERROR(INDEX(Presupuesto!$M$9:$M$1008,MATCH(27,Presupuesto!$O$9:$O$1008,0)),"") | C31: =IF(B31="","",COUNTIF(Presupuesto!$M$9:$M$1008,B31)) | D31: =IF(B31="","",SUMIF(Presupuesto!$M$9:$M$1008,B31,Presupuesto!$J$9:$J$1008)) | E31: =IF(OR(B31="",$D$45=0),"",D31/$D$45)
B32: =IFERROR(INDEX(Presupuesto!$M$9:$M$1008,MATCH(28,Presupuesto!$O$9:$O$1008,0)),"") | C32: =IF(B32="","",COUNTIF(Presupuesto!$M$9:$M$1008,B32)) | D32: =IF(B32="","",SUMIF(Presupuesto!$M$9:$M$1008,B32,Presupuesto!$J$9:$J$1008)) | E32: =IF(OR(B32="",$D$45=0),"",D32/$D$45)
B33: =IFERROR(INDEX(Presupuesto!$M$9:$M$1008,MATCH(29,Presupuesto!$O$9:$O$1008,0)),"") | C33: =IF(B33="","",COUNTIF(Presupuesto!$M$9:$M$1008,B33)) | D33: =IF(B33="","",SUMIF(Presupuesto!$M$9:$M$1008,B33,Presupuesto!$J$9:$J$1008)) | E33: =IF(OR(B33="",$D$45=0),"",D33/$D$45)
B34: =IFERROR(INDEX(Presupuesto!$M$9:$M$1008,MATCH(30,Presupuesto!$O$9:$O$1008,0)),"") | C34: =IF(B34="","",COUNTIF(Presupuesto!$M$9:$M$1008,B34)) | D34: =IF(B34="","",SUMIF(Presupuesto!$M$9:$M$1008,B34,Presupuesto!$J$9:$J$1008)) | E34: =IF(OR(B34="",$D$45=0),"",D34/$D$45)
B35: =IFERROR(INDEX(Presupuesto!$M$9:$M$1008,MATCH(31,Presupuesto!$O$9:$O$1008,0)),"") | C35: =IF(B35="","",COUNTIF(Presupuesto!$M$9:$M$1008,B35)) | D35: =IF(B35="","",SUMIF(Presupuesto!$M$9:$M$1008,B35,Presupuesto!$J$9:$J$1008)) | E35: =IF(OR(B35="",$D$45=0),"",D35/$D$45)
B36: =IFERROR(INDEX(Presupuesto!$M$9:$M$1008,MATCH(32,Presupuesto!$O$9:$O$1008,0)),"") | C36: =IF(B36="","",COUNTIF(Presupuesto!$M$9:$M$1008,B36)) | D36: =IF(B36="","",SUMIF(Presupuesto!$M$9:$M$1008,B36,Presupuesto!$J$9:$J$1008)) | E36: =IF(OR(B36="",$D$45=0),"",D36/$D$45)
B37: =IFERROR(INDEX(Presupuesto!$M$9:$M$1008,MATCH(33,Presupuesto!$O$9:$O$1008,0)),"") | C37: =IF(B37="","",COUNTIF(Presupuesto!$M$9:$M$1008,B37)) | D37: =IF(B37="","",SUMIF(Presupuesto!$M$9:$M$1008,B37,Presupuesto!$J$9:$J$1008)) | E37: =IF(OR(B37="",$D$45=0),"",D37/$D$45)
B38: =IFERROR(INDEX(Presupuesto!$M$9:$M$1008,MATCH(34,Presupuesto!$O$9:$O$1008,0)),"") | C38: =IF(B38="","",COUNTIF(Presupuesto!$M$9:$M$1008,B38)) | D38: =IF(B38="","",SUMIF(Presupuesto!$M$9:$M$1008,B38,Presupuesto!$J$9:$J$1008)) | E38: =IF(OR(B38="",$D$45=0),"",D38/$D$45)
B39: =IFERROR(INDEX(Presupuesto!$M$9:$M$1008,MATCH(35,Presupuesto!$O$9:$O$1008,0)),"") | C39: =IF(B39="","",COUNTIF(Presupuesto!$M$9:$M$1008,B39)) | D39: =IF(B39="","",SUMIF(Presupuesto!$M$9:$M$1008,B39,Presupuesto!$J$9:$J$1008)) | E39: =IF(OR(B39="",$D$45=0),"",D39/$D$45)
B40: =IFERROR(INDEX(Presupuesto!$M$9:$M$1008,MATCH(36,Presupuesto!$O$9:$O$1008,0)),"") | C40: =IF(B40="","",COUNTIF(Presupuesto!$M$9:$M$1008,B40)) | D40: =IF(B40="","",SUMIF(Presupuesto!$M$9:$M$1008,B40,Presupuesto!$J$9:$J$1008)) | E40: =IF(OR(B40="",$D$45=0),"",D40/$D$45)
B41: =IFERROR(INDEX(Presupuesto!$M$9:$M$1008,MATCH(37,Presupuesto!$O$9:$O$1008,0)),"") | C41: =IF(B41="","",COUNTIF(Presupuesto!$M$9:$M$1008,B41)) | D41: =IF(B41="","",SUMIF(Presupuesto!$M$9:$M$1008,B41,Presupuesto!$J$9:$J$1008)) | E41: =IF(OR(B41="",$D$45=0),"",D41/$D$45)
...

Sheet Listas
A1: Unidades | B1: Capítulos | C1: Sectores | D1: Variantes aceptadas
A2: m2 | B2: PRELIMINARES | C2: Planta baja | D2: M2
A3: ml | B3: DEMOLICIONES | C3: Subsuelo | D3: m²
A4: m3 | B4: MAMPOSTERÍA | C4: Nivel 1 | D4: mts2
A5: m | B5: ESTRUCTURA DE HORMIGÓN | C5: Nivel 2 | D5: ML
A6: un | B6: REVOQUES | C6: Nivel 3 | D6: mts
A7: gl | B7: CONTRAPISOS Y CARPETAS | C7: Nivel 4 | D7: mt
A8: kg | B8: PISOS Y REVESTIMIENTOS | C8: Nivel 5 | D8: M3
A9: viaje | B9: CIELORRASOS | C9: Nivel 6 | D9: m³
A10: mes | B10: PINTURA | C10: Nivel 7 | D10: Unid.
A11: día | B11: ABERTURAS | C11: Nivel 8 | D11: unid
A12: jor | B12: INSTALACIÓN SANITARIA | C12: Terraza | D12: unid.
A13: hs | B13: INSTALACIÓN ELÉCTRICA | C13: Fachada | D13: u
B14: IMPERMEABILIZACIÓN | C14: General | D14: und
B15: AYUDA DE GREMIOS | D15: uni
B16: LIMPIEZA Y VARIOS | D16: gb
D17: glb
D18: global
D19: viajes
D20: dia
D21: dias
D22: días
D23: jornal
D24: jornales
D25: hora
D26: horas
D27: meses
D28: kgs
... D30: pieza
